Workbook

Sheet Outputs
A1: MU model v1: outputs
A2: Prepared by Delta, Quant. Draft until the Captain approves it; approved versions are the firm's official numbers.
A4: Scenario | B4: Price target | C4: Price return | D4: Total return | E4: DCF value today | F4: WACC | G4: TV share of EV
A5: Bull | B5: ='Calc Bull'!$B$71 | C5: ='Calc Bull'!$B$75 | D5: ='Calc Bull'!$B$76 | E5: ='Calc Bull'!$B$58 | F5: ='Calc Bull'!$B$38 | G5: ='Calc Bull'!$B$59
A6: Base | B6: ='Calc Base'!$B$71 | C6: ='Calc Base'!$B$75 | D6: ='Calc Base'!$B$76 | E6: ='Calc Base'!$B$58 | F6: ='Calc Base'!$B$38 | G6: ='Calc Base'!$B$59
A7: Bear | B7: ='Calc Bear'!$B$71 | C7: ='Calc Bear'!$B$75 | D7: ='Calc Bear'!$B$76 | E7: ='Calc Bear'!$B$58 | F7: ='Calc Bear'!$B$38 | G7: ='Calc Bear'!$B$59
A9: Base case: method values
A10: dcf | B10: ='Calc Base'!$B$68 | C10: ='Calc Base'!$B$72
A11: pe | B11: ='Calc Base'!$B$69 | C11: ='Calc Base'!$B$73
A12: ev_ebitda | B12: ='Calc Base'!$B$70 | C12: ='Calc Base'!$B$74
A14: Rating
A15: S&P 500 expected return over the horizon | B15: =(1+Inputs!$B$69)^'Calc Base'!$B$62-1
A16: Base-case excess return | B16: ='Calc Base'!$B$76-Outputs!$B$15
A17: Rating | B17: =IF(Outputs!$B$16>Inputs!$B$70,"Outperform",IF(Outputs!$B$16<-Inputs!$B$70,"Underperform","Neutral"))
A19: Sensitivity: base-case DCF value at the target date
A20: Steps (inputs) | C20: -2 | D20: -1 | E20: 0 | F20: 1 | G20: 2
A21: WACC step (input) / WACC | B21: Exit EV/EBITDA | C21: =Inputs!$B$46+C20 | D21: =Inputs!$B$46+D20 | E21: =Inputs!$B$46+E20 | F21: =Inputs!$B$46+F20 | G21: =Inputs!$B$46+G20
A22: -0.01 | B22: ='Calc Base'!$B$38+A22 | C22: =(('Calc Base'!$C$32*'Calc Base'!$C$47*(1+$B22)^-'Calc Base'!$C$48+'Calc Base'!$D$32*'Calc Base'!$D$47*(1+$B22)^-'Calc Base'!$D$48+'Calc Base'!$E$32*'Calc Base'!$E$47*(1+$B22)^-'Calc Base'!$E$48+'Calc Base'!$F$32*'Calc Base'!$F$47*(1+$B22)^-'Calc Base'!$F$48+'Calc Base'!$G$32*'Calc Base'!$G$47*(1+$B22)^-'Calc Base'!$G$48)+C$21*'Calc Base'!$G$20*(1+$B22)^-'Calc Base'!$B$52-Inputs!$B$12)/Inputs!$B$11*Inputs!$B$14/Inputs!$B$15*(1+'Calc Base'!$B$35)^'Calc Base'!$B$62-Inputs!$B$13*'Calc Base'!$B$62 | D22: =(('Calc Base'!$C$32*'Calc Base'!$C$47*(1+$B22)^-'Calc Base'!$C$48+'Calc Base'!$D$32*'Calc Base'!$D$47*(1+$B22)^-'Calc Base'!$D$48+'Calc Base'!$E$32*'Calc Base'!$E$47*(1+$B22)^-'Calc Base'!$E$48+'Calc Base'!$F$32*'Calc Base'!$F$47*(1+$B22)^-'Calc Base'!$F$48+'Calc Base'!$G$32*'Calc Base'!$G$47*(1+$B22)^-'Calc Base'!$G$48)+D$21*'Calc Base'!$G$20*(1+$B22)^-'Calc Base'!$B$52-Inputs!$B$12)/Inputs!$B$11*Inputs!$B$14/Inputs!$B$15*(1+'Calc Base'!$B$35)^'Calc Base'!$B$62-Inputs!$B$13*'Calc Base'!$B$62 | E22: =(('Calc Base'!$C$32*'Calc Base'!$C$47*(1+$B22)^-'Calc Base'!$C$48+'Calc Base'!$D$32*'Calc Base'!$D$47*(1+$B22)^-'Calc Base'!$D$48+'Calc Base'!$E$32*'Calc Base'!$E$47*(1+$B22)^-'Calc Base'!$E$48+'Calc Base'!$F$32*'Calc Base'!$F$47*(1+$B22)^-'Calc Base'!$F$48+'Calc Base'!$G$32*'Calc Base'!$G$47*(1+$B22)^-'Calc Base'!$G$48)+E$21*'Calc Base'!$G$20*(1+$B22)^-'Calc Base'!$B$52-Inputs!$B$12)/Inputs!$B$11*Inputs!$B$14/Inputs!$B$15*(1+'Calc Base'!$B$35)^'Calc Base'!$B$62-Inputs!$B$13*'Calc Base'!$B$62 | F22: =(('Calc Base'!$C$32*'Calc Base'!$C$47*(1+$B22)^-'Calc Base'!$C$48+'Calc Base'!$D$32*'Calc Base'!$D$47*(1+$B22)^-'Calc Base'!$D$48+'Calc Base'!$E$32*'Calc Base'!$E$47*(1+$B22)^-'Calc Base'!$E$48+'Calc Base'!$F$32*'Calc Base'!$F$47*(1+$B22)^-'Calc Base'!$F$48+'Calc Base'!$G$32*'Calc Base'!$G$47*(1+$B22)^-'Calc Base'!$G$48)+F$21*'Calc Base'!$G$20*(1+$B22)^-'Calc Base'!$B$52-Inputs!$B$12)/Inputs!$B$11*Inputs!$B$14/Inputs!$B$15*(1+'Calc Base'!$B$35)^'Calc Base'!$B$62-Inputs!$B$13*'Calc Base'!$B$62 | G22: =(('Calc Base'!$C$32*'Calc Base'!$C$47*(1+$B22)^-'Calc Base'!$C$48+'Calc Base'!$D$32*'Calc Base'!$D$47*(1+$B22)^-'Calc Base'!$D$48+'Calc Base'!$E$32*'Calc Base'!$E$47*(1+$B22)^-'Calc Base'!$E$48+'Calc Base'!$F$32*'Calc Base'!$F$47*(1+$B22)^-'Calc Base'!$F$48+'Calc Base'!$G$32*'Calc Base'!$G$47*(1+$B22)^-'Calc Base'!$G$48)+G$21*'Calc Base'!$G$20*(1+$B22)^-'Calc Base'!$B$52-Inputs!$B$12)/Inputs!$B$11*Inputs!$B$14/Inputs!$B$15*(1+'Calc Base'!$B$35)^'Calc Base'!$B$62-Inputs!$B$13*'Calc Base'!$B$62
A23: -0.005 | B23: ='Calc Base'!$B$38+A23 | C23: =(('Calc Base'!$C$32*'Calc Base'!$C$47*(1+$B23)^-'Calc Base'!$C$48+'Calc Base'!$D$32*'Calc Base'!$D$47*(1+$B23)^-'Calc Base'!$D$48+'Calc Base'!$E$32*'Calc Base'!$E$47*(1+$B23)^-'Calc Base'!$E$48+'Calc Base'!$F$32*'Calc Base'!$F$47*(1+$B23)^-'Calc Base'!$F$48+'Calc Base'!$G$32*'Calc Base'!$G$47*(1+$B23)^-'Calc Base'!$G$48)+C$21*'Calc Base'!$G$20*(1+$B23)^-'Calc Base'!$B$52-Inputs!$B$12)/Inputs!$B$11*Inputs!$B$14/Inputs!$B$15*(1+'Calc Base'!$B$35)^'Calc Base'!$B$62-Inputs!$B$13*'Calc Base'!$B$62 | D23: =(('Calc Base'!$C$32*'Calc Base'!$C$47*(1+$B23)^-'Calc Base'!$C$48+'Calc Base'!$D$32*'Calc Base'!$D$47*(1+$B23)^-'Calc Base'!$D$48+'Calc Base'!$E$32*'Calc Base'!$E$47*(1+$B23)^-'Calc Base'!$E$48+'Calc Base'!$F$32*'Calc Base'!$F$47*(1+$B23)^-'Calc Base'!$F$48+'Calc Base'!$G$32*'Calc Base'!$G$47*(1+$B23)^-'Calc Base'!$G$48)+D$21*'Calc Base'!$G$20*(1+$B23)^-'Calc Base'!$B$52-Inputs!$B$12)/Inputs!$B$11*Inputs!$B$14/Inputs!$B$15*(1+'Calc Base'!$B$35)^'Calc Base'!$B$62-Inputs!$B$13*'Calc Base'!$B$62 | E23: =(('Calc Base'!$C$32*'Calc Base'!$C$47*(1+$B23)^-'Calc Base'!$C$48+'Calc Base'!$D$32*'Calc Base'!$D$47*(1+$B23)^-'Calc Base'!$D$48+'Calc Base'!$E$32*'Calc Base'!$E$47*(1+$B23)^-'Calc Base'!$E$48+'Calc Base'!$F$32*'Calc Base'!$F$47*(1+$B23)^-'Calc Base'!$F$48+'Calc Base'!$G$32*'Calc Base'!$G$47*(1+$B23)^-'Calc Base'!$G$48)+E$21*'Calc Base'!$G$20*(1+$B23)^-'Calc Base'!$B$52-Inputs!$B$12)/Inputs!$B$11*Inputs!$B$14/Inputs!$B$15*(1+'Calc Base'!$B$35)^'Calc Base'!$B$62-Inputs!$B$13*'Calc Base'!$B$62 | F23: =(('Calc Base'!$C$32*'Calc Base'!$C$47*(1+$B23)^-'Calc Base'!$C$48+'Calc Base'!$D$32*'Calc Base'!$D$47*(1+$B23)^-'Calc Base'!$D$48+'Calc Base'!$E$32*'Calc Base'!$E$47*(1+$B23)^-'Calc Base'!$E$48+'Calc Base'!$F$32*'Calc Base'!$F$47*(1+$B23)^-'Calc Base'!$F$48+'Calc Base'!$G$32*'Calc Base'!$G$47*(1+$B23)^-'Calc Base'!$G$48)+F$21*'Calc Base'!$G$20*(1+$B23)^-'Calc Base'!$B$52-Inputs!$B$12)/Inputs!$B$11*Inputs!$B$14/Inputs!$B$15*(1+'Calc Base'!$B$35)^'Calc Base'!$B$62-Inputs!$B$13*'Calc Base'!$B$62 | G23: =(('Calc Base'!$C$32*'Calc Base'!$C$47*(1+$B23)^-'Calc Base'!$C$48+'Calc Base'!$D$32*'Calc Base'!$D$47*(1+$B23)^-'Calc Base'!$D$48+'Calc Base'!$E$32*'Calc Base'!$E$47*(1+$B23)^-'Calc Base'!$E$48+'Calc Base'!$F$32*'Calc Base'!$F$47*(1+$B23)^-'Calc Base'!$F$48+'Calc Base'!$G$32*'Calc Base'!$G$47*(1+$B23)^-'Calc Base'!$G$48)+G$21*'Calc Base'!$G$20*(1+$B23)^-'Calc Base'!$B$52-Inputs!$B$12)/Inputs!$B$11*Inputs!$B$14/Inputs!$B$15*(1+'Calc Base'!$B$35)^'Calc Base'!$B$62-Inputs!$B$13*'Calc Base'!$B$62
A24: 0 | B24: ='Calc Base'!$B$38+A24 | C24: =(('Calc Base'!$C$32*'Calc Base'!$C$47*(1+$B24)^-'Calc Base'!$C$48+'Calc Base'!$D$32*'Calc Base'!$D$47*(1+$B24)^-'Calc Base'!$D$48+'Calc Base'!$E$32*'Calc Base'!$E$47*(1+$B24)^-'Calc Base'!$E$48+'Calc Base'!$F$32*'Calc Base'!$F$47*(1+$B24)^-'Calc Base'!$F$48+'Calc Base'!$G$32*'Calc Base'!$G$47*(1+$B24)^-'Calc Base'!$G$48)+C$21*'Calc Base'!$G$20*(1+$B24)^-'Calc Base'!$B$52-Inputs!$B$12)/Inputs!$B$11*Inputs!$B$14/Inputs!$B$15*(1+'Calc Base'!$B$35)^'Calc Base'!$B$62-Inputs!$B$13*'Calc Base'!$B$62 | D24: =(('Calc Base'!$C$32*'Calc Base'!$C$47*(1+$B24)^-'Calc Base'!$C$48+'Calc Base'!$D$32*'Calc Base'!$D$47*(1+$B24)^-'Calc Base'!$D$48+'Calc Base'!$E$32*'Calc Base'!$E$47*(1+$B24)^-'Calc Base'!$E$48+'Calc Base'!$F$32*'Calc Base'!$F$47*(1+$B24)^-'Calc Base'!$F$48+'Calc Base'!$G$32*'Calc Base'!$G$47*(1+$B24)^-'Calc Base'!$G$48)+D$21*'Calc Base'!$G$20*(1+$B24)^-'Calc Base'!$B$52-Inputs!$B$12)/Inputs!$B$11*Inputs!$B$14/Inputs!$B$15*(1+'Calc Base'!$B$35)^'Calc Base'!$B$62-Inputs!$B$13*'Calc Base'!$B$62 | E24: =(('Calc Base'!$C$32*'Calc Base'!$C$47*(1+$B24)^-'Calc Base'!$C$48+'Calc Base'!$D$32*'Calc Base'!$D$47*(1+$B24)^-'Calc Base'!$D$48+'Calc Base'!$E$32*'Calc Base'!$E$47*(1+$B24)^-'Calc Base'!$E$48+'Calc Base'!$F$32*'Calc Base'!$F$47*(1+$B24)^-'Calc Base'!$F$48+'Calc Base'!$G$32*'Calc Base'!$G$47*(1+$B24)^-'Calc Base'!$G$48)+E$21*'Calc Base'!$G$20*(1+$B24)^-'Calc Base'!$B$52-Inputs!$B$12)/Inputs!$B$11*Inputs!$B$14/Inputs!$B$15*(1+'Calc Base'!$B$35)^'Calc Base'!$B$62-Inputs!$B$13*'Calc Base'!$B$62 | F24: =(('Calc Base'!$C$32*'Calc Base'!$C$47*(1+$B24)^-'Calc Base'!$C$48+'Calc Base'!$D$32*'Calc Base'!$D$47*(1+$B24)^-'Calc Base'!$D$48+'Calc Base'!$E$32*'Calc Base'!$E$47*(1+$B24)^-'Calc Base'!$E$48+'Calc Base'!$F$32*'Calc Base'!$F$47*(1+$B24)^-'Calc Base'!$F$48+'Calc Base'!$G$32*'Calc Base'!$G$47*(1+$B24)^-'Calc Base'!$G$48)+F$21*'Calc Base'!$G$20*(1+$B24)^-'Calc Base'!$B$52-Inputs!$B$12)/Inputs!$B$11*Inputs!$B$14/Inputs!$B$15*(1+'Calc Base'!$B$35)^'Calc Base'!$B$62-Inputs!$B$13*'Calc Base'!$B$62 | G24: =(('Calc Base'!$C$32*'Calc Base'!$C$47*(1+$B24)^-'Calc Base'!$C$48+'Calc Base'!$D$32*'Calc Base'!$D$47*(1+$B24)^-'Calc Base'!$D$48+'Calc Base'!$E$32*'Calc Base'!$E$47*(1+$B24)^-'Calc Base'!$E$48+'Calc Base'!$F$32*'Calc Base'!$F$47*(1+$B24)^-'Calc Base'!$F$48+'Calc Base'!$G$32*'Calc Base'!$G$47*(1+$B24)^-'Calc Base'!$G$48)+G$21*'Calc Base'!$G$20*(1+$B24)^-'Calc Base'!$B$52-Inputs!$B$12)/Inputs!$B$11*Inputs!$B$14/Inputs!$B$15*(1+'Calc Base'!$B$35)^'Calc Base'!$B$62-Inputs!$B$13*'Calc Base'!$B$62
A25: 0.005 | B25: ='Calc Base'!$B$38+A25 | C25: =(('Calc Base'!$C$32*'Calc Base'!$C$47*(1+$B25)^-'Calc Base'!$C$48+'Calc Base'!$D$32*'Calc Base'!$D$47*(1+$B25)^-'Calc Base'!$D$48+'Calc Base'!$E$32*'Calc Base'!$E$47*(1+$B25)^-'Calc Base'!$E$48+'Calc Base'!$F$32*'Calc Base'!$F$47*(1+$B25)^-'Calc Base'!$F$48+'Calc Base'!$G$32*'Calc Base'!$G$47*(1+$B25)^-'Calc Base'!$G$48)+C$21*'Calc Base'!$G$20*(1+$B25)^-'Calc Base'!$B$52-Inputs!$B$12)/Inputs!$B$11*Inputs!$B$14/Inputs!$B$15*(1+'Calc Base'!$B$35)^'Calc Base'!$B$62-Inputs!$B$13*'Calc Base'!$B$62 | D25: =(('Calc Base'!$C$32*'Calc Base'!$C$47*(1+$B25)^-'Calc Base'!$C$48+'Calc Base'!$D$32*'Calc Base'!$D$47*(1+$B25)^-'Calc Base'!$D$48+'Calc Base'!$E$32*'Calc Base'!$E$47*(1+$B25)^-'Calc Base'!$E$48+'Calc Base'!$F$32*'Calc Base'!$F$47*(1+$B25)^-'Calc Base'!$F$48+'Calc Base'!$G$32*'Calc Base'!$G$47*(1+$B25)^-'Calc Base'!$G$48)+D$21*'Calc Base'!$G$20*(1+$B25)^-'Calc Base'!$B$52-Inputs!$B$12)/Inputs!$B$11*Inputs!$B$14/Inputs!$B$15*(1+'Calc Base'!$B$35)^'Calc Base'!$B$62-Inputs!$B$13*'Calc Base'!$B$62 | E25: =(('Calc Base'!$C$32*'Calc Base'!$C$47*(1+$B25)^-'Calc Base'!$C$48+'Calc Base'!$D$32*'Calc Base'!$D$47*(1+$B25)^-'Calc Base'!$D$48+'Calc Base'!$E$32*'Calc Base'!$E$47*(1+$B25)^-'Calc Base'!$E$48+'Calc Base'!$F$32*'Calc Base'!$F$47*(1+$B25)^-'Calc Base'!$F$48+'Calc Base'!$G$32*'Calc Base'!$G$47*(1+$B25)^-'Calc Base'!$G$48)+E$21*'Calc Base'!$G$20*(1+$B25)^-'Calc Base'!$B$52-Inputs!$B$12)/Inputs!$B$11*Inputs!$B$14/Inputs!$B$15*(1+'Calc Base'!$B$35)^'Calc Base'!$B$62-Inputs!$B$13*'Calc Base'!$B$62 | F25: =(('Calc Base'!$C$32*'Calc Base'!$C$47*(1+$B25)^-'Calc Base'!$C$48+'Calc Base'!$D$32*'Calc Base'!$D$47*(1+$B25)^-'Calc Base'!$D$48+'Calc Base'!$E$32*'Calc Base'!$E$47*(1+$B25)^-'Calc Base'!$E$48+'Calc Base'!$F$32*'Calc Base'!$F$47*(1+$B25)^-'Calc Base'!$F$48+'Calc Base'!$G$32*'Calc Base'!$G$47*(1+$B25)^-'Calc Base'!$G$48)+F$21*'Calc Base'!$G$20*(1+$B25)^-'Calc Base'!$B$52-Inputs!$B$12)/Inputs!$B$11*Inputs!$B$14/Inputs!$B$15*(1+'Calc Base'!$B$35)^'Calc Base'!$B$62-Inputs!$B$13*'Calc Base'!$B$62 | G25: =(('Calc Base'!$C$32*'Calc Base'!$C$47*(1+$B25)^-'Calc Base'!$C$48+'Calc Base'!$D$32*'Calc Base'!$D$47*(1+$B25)^-'Calc Base'!$D$48+'Calc Base'!$E$32*'Calc Base'!$E$47*(1+$B25)^-'Calc Base'!$E$48+'Calc Base'!$F$32*'Calc Base'!$F$47*(1+$B25)^-'Calc Base'!$F$48+'Calc Base'!$G$32*'Calc Base'!$G$47*(1+$B25)^-'Calc Base'!$G$48)+G$21*'Calc Base'!$G$20*(1+$B25)^-'Calc Base'!$B$52-Inputs!$B$12)/Inputs!$B$11*Inputs!$B$14/Inputs!$B$15*(1+'Calc Base'!$B$35)^'Calc Base'!$B$62-Inputs!$B$13*'Calc Base'!$B$62
A26: 0.01 | B26: ='Calc Base'!$B$38+A26 | C26: =(('Calc Base'!$C$32*'Calc Base'!$C$47*(1+$B26)^-'Calc Base'!$C$48+'Calc Base'!$D$32*'Calc Base'!$D$47*(1+$B26)^-'Calc Base'!$D$48+'Calc Base'!$E$32*'Calc Base'!$E$47*(1+$B26)^-'Calc Base'!$E$48+'Calc Base'!$F$32*'Calc Base'!$F$47*(1+$B26)^-'Calc Base'!$F$48+'Calc Base'!$G$32*'Calc Base'!$G$47*(1+$B26)^-'Calc Base'!$G$48)+C$21*'Calc Base'!$G$20*(1+$B26)^-'Calc Base'!$B$52-Inputs!$B$12)/Inputs!$B$11*Inputs!$B$14/Inputs!$B$15*(1+'Calc Base'!$B$35)^'Calc Base'!$B$62-Inputs!$B$13*'Calc Base'!$B$62 | D26: =(('Calc Base'!$C$32*'Calc Base'!$C$47*(1+$B26)^-'Calc Base'!$C$48+'Calc Base'!$D$32*'Calc Base'!$D$47*(1+$B26)^-'Calc Base'!$D$48+'Calc Base'!$E$32*'Calc Base'!$E$47*(1+$B26)^-'Calc Base'!$E$48+'Calc Base'!$F$32*'Calc Base'!$F$47*(1+$B26)^-'Calc Base'!$F$48+'Calc Base'!$G$32*'Calc Base'!$G$47*(1+$B26)^-'Calc Base'!$G$48)+D$21*'Calc Base'!$G$20*(1+$B26)^-'Calc Base'!$B$52-Inputs!$B$12)/Inputs!$B$11*Inputs!$B$14/Inputs!$B$15*(1+'Calc Base'!$B$35)^'Calc Base'!$B$62-Inputs!$B$13*'Calc Base'!$B$62 | E26: =(('Calc Base'!$C$32*'Calc Base'!$C$47*(1+$B26)^-'Calc Base'!$C$48+'Calc Base'!$D$32*'Calc Base'!$D$47*(1+$B26)^-'Calc Base'!$D$48+'Calc Base'!$E$32*'Calc Base'!$E$47*(1+$B26)^-'Calc Base'!$E$48+'Calc Base'!$F$32*'Calc Base'!$F$47*(1+$B26)^-'Calc Base'!$F$48+'Calc Base'!$G$32*'Calc Base'!$G$47*(1+$B26)^-'Calc Base'!$G$48)+E$21*'Calc Base'!$G$20*(1+$B26)^-'Calc Base'!$B$52-Inputs!$B$12)/Inputs!$B$11*Inputs!$B$14/Inputs!$B$15*(1+'Calc Base'!$B$35)^'Calc Base'!$B$62-Inputs!$B$13*'Calc Base'!$B$62 | F26: =(('Calc Base'!$C$32*'Calc Base'!$C$47*(1+$B26)^-'Calc Base'!$C$48+'Calc Base'!$D$32*'Calc Base'!$D$47*(1+$B26)^-'Calc Base'!$D$48+'Calc Base'!$E$32*'Calc Base'!$E$47*(1+$B26)^-'Calc Base'!$E$48+'Calc Base'!$F$32*'Calc Base'!$F$47*(1+$B26)^-'Calc Base'!$F$48+'Calc Base'!$G$32*'Calc Base'!$G$47*(1+$B26)^-'Calc Base'!$G$48)+F$21*'Calc Base'!$G$20*(1+$B26)^-'Calc Base'!$B$52-Inputs!$B$12)/Inputs!$B$11*Inputs!$B$14/Inputs!$B$15*(1+'Calc Base'!$B$35)^'Calc Base'!$B$62-Inputs!$B$13*'Calc Base'!$B$62 | G26: =(('Calc Base'!$C$32*'Calc Base'!$C$47*(1+$B26)^-'Calc Base'!$C$48+'Calc Base'!$D$32*'Calc Base'!$D$47*(1+$B26)^-'Calc Base'!$D$48+'Calc Base'!$E$32*'Calc Base'!$E$47*(1+$B26)^-'Calc Base'!$E$48+'Calc Base'!$F$32*'Calc Base'!$F$47*(1+$B26)^-'Calc Base'!$F$48+'Calc Base'!$G$32*'Calc Base'!$G$47*(1+$B26)^-'Calc Base'!$G$48)+G$21*'Calc Base'!$G$20*(1+$B26)^-'Calc Base'!$B$52-Inputs!$B$12)/Inputs!$B$11*Inputs!$B$14/Inputs!$B$15*(1+'Calc Base'!$B$35)^'Calc Base'!$B$62-Inputs!$B$13*'Calc Base'!$B$62

Sheet Inputs
A1: MU valuation inputs
A2: Blue = input (edit these). Every calculation references this tab.
H3: Notes (reasons carried over from assumptions.yaml)
A5: General
A6: Share price | B6: 1062.29 | H6: USD, Yahoo [S5]
A7: Price date (as of) | B7: 46300 | H7: price date (previous close) [S5]
A8: Horizon (months) | B8: 15 | H8: 12-18 month horizon
A9: Months per year | B9: 12
A10: Days per year (for date fractions) | B10: 365.25
A11: Diluted shares | B11: 1147000000 | H11: why: FQ4-26 diluted weighted shares, 1,147 mn [S4]
A12: Net debt | B12: -68274000000 | H12: why: total debt $5.179 bn (current $0.491 bn + long-term $4.688 bn) less cash $38.364 bn, short-term investments $5.070 bn and long-term marketable investments $30.019 bn = net cash $68.274 bn at 2026-09-03; restricted cash excluded [S4]
A13: Dividend per share (annual) | B13: 0.6 | H13: why: $0.15 per quarter declared 2026-09-30 [S4]
A14: Ordinary shares per traded unit | B14: 1
A15: Local currency per trading currency | B15: 1
A17: Timing
A18: Fiscal year | B18: FY2026A | C18: 2027 | D18: 2028 | E18: 2029 | F18: 2030 | G18: 2031
A19: Fiscal year end | C19: 46633 | D19: 46999 | E19: 47364 | F19: 47729 | G19: 48094
A21: Revenue
A22: Growth by segment (base in column B) | B22: FY2026A | C22: 2027 | D22: 2028 | E22: 2029 | F22: 2030 | G22: 2031
A23: Total | B23: 133188000000 | C23: 1.0642 | D23: 0.1427 | E23: 0.03 | F23: 0.03 | G23: 0.03
A25: Margins and cash flow
A26: Fiscal year | B26: FY2026A | C26: 2027 | D26: 2028 | E26: 2029 | F26: 2030 | G26: 2031
A27: EBITDA margin | C27: 0.83 | D27: 0.76 | E27: 0.68 | F27: 0.66 | G27: 0.65
A28: CapEx % revenue | C28: 0.137 | D28: 0.167 | E28: 0.156 | F28: 0.13 | G28: 0.125
A29: Tax rate | C29: 0.15 | D29: 0.15 | E29: 0.15 | F29: 0.15 | G29: 0.15 | H29: why: FY26 provision $14.76 bn on pre-tax income $99.67 bn is 14.8% [S4]
A30: Other income % revenue | C30: 0.002 | D30: 0.002 | E30: 0.002 | F30: 0.002 | G30: 0.002 | H30: why: FY26 interest income $1.08 bn less interest expense $0.11 bn and other $(0.65) bn is +$0.33 bn, 0.2% of revenue [S4]
A31: Share count change | C31: 0.002 | D31: 0.002 | E31: 0.002 | F31: 0.002 | G31: 0.002 | H31: why: diluted shares 1,125 mn (FY25) to 1,143 mn (FY26) is +1.6%, but buybacks and withholdings offset; hold close to flat [S4]
A32: Change in NWC per $ of revenue growth | C32: 0.12 | D32: 0.12 | E32: 0.12 | F32: 0.12 | G32: 0.12 | H32: why: FY26 working capital absorbed about $15.4 bn (receivables $(25.2) bn, inventories $(2.0) bn, payables +$8.7 bn, other current +$3.1 bn) on $95.8 bn of added revenue = 16%; customer deposits offset part of it, so 12% [S4]
A33: Net PP&E (base year) | B33: 63310000000 | H33: why: net PP&E $63.31 bn at 2026-09-03; life 6.5 years implied by FY26 D&A of $9.50 bn on opening PP&E plus half of capex [S4]
A34: Useful life (years) | B34: 6.5
A36: Cost of capital (CAPM)
A37: Risk-free rate | B37: 0.0531 | H37: 10Y UST yield (^TNX), 2026-10-05 [S5]
A38: Beta | B38: 2.23 | H38: Yahoo 5Y monthly beta; high because of the FY23 drawdown [S1][S5]
A39: Equity risk premium | B39: 0.045 | H39: confirmed by Stott 2026-10-05
A40: Pre-tax cost of debt | B40: 0.0834 | H40: draft default, bounded rf to rf+5%; debt is 0.4% of capital so the effect is nil
A41: Tax rate for the debt shield | B41: 0.21
A42: Equity value (market cap) | B42: 1199584968704 | H42: market cap (USD) [S5]
A43: Debt value | B43: 5179000000 | H43: why: total debt at 2026-09-03 [S4]
A45: Terminal value
A46: Exit EV/EBITDA | B46: 6
...

Sheet Calc Base
A1: MU base case: calculations
A2: All formulas. Inputs live on the Inputs tab.
A5: Scenario
A6: Growth delta | B6: =Inputs!$B$62
A7: Margin delta (by final year) | B7: =Inputs!$C$62
A8: Multiple factor | B8: =1+Inputs!$D$62
A9: WACC delta | B9: =Inputs!$E$62
A11: Projections
A12: Fiscal year | B12: FY2026A | C12: 2027 | D12: 2028 | E12: 2029 | F12: 2030 | G12: 2031
A13: Projection year | C13: =1 | D13: =C13+1 | E13: =D13+1 | F13: =E13+1 | G13: =F13+1
A14: Total: growth | C14: =Inputs!$C$23+'Calc Base'!$B$6 | D14: =Inputs!$D$23+'Calc Base'!$B$6 | E14: =Inputs!$E$23+'Calc Base'!$B$6 | F14: =Inputs!$F$23+'Calc Base'!$B$6 | G14: =Inputs!$G$23+'Calc Base'!$B$6
A15: Total: revenue | B15: =Inputs!$B$23 | C15: =B15*(1+C14) | D15: =C15*(1+D14) | E15: =D15*(1+E14) | F15: =E15*(1+F14) | G15: =F15*(1+G14)
A16: Revenue | B16: =B15 | C16: =C15 | D16: =D15 | E16: =E15 | F16: =F15 | G16: =G15
A17: Revenue growth | C17: =C16/B16-1 | D17: =D16/C16-1 | E17: =E16/D16-1 | F17: =F16/E16-1 | G17: =G16/F16-1
A18: Margin delta ramp | C18: =C13/$G$13 | D18: =D13/$G$13 | E18: =E13/$G$13 | F18: =F13/$G$13 | G18: =G13/$G$13
A19: EBITDA margin | C19: =Inputs!$C$27+'Calc Base'!$B$7*C18 | D19: =Inputs!$D$27+'Calc Base'!$B$7*D18 | E19: =Inputs!$E$27+'Calc Base'!$B$7*E18 | F19: =Inputs!$F$27+'Calc Base'!$B$7*F18 | G19: =Inputs!$G$27+'Calc Base'!$B$7*G18
A20: EBITDA | C20: =C16*C19 | D20: =D16*D19 | E20: =E16*E19 | F20: =F16*F19 | G20: =G16*G19
A21: CapEx | C21: =C16*Inputs!$C$28 | D21: =D16*Inputs!$D$28 | E21: =E16*Inputs!$E$28 | F21: =F16*Inputs!$F$28 | G21: =G16*Inputs!$G$28
A22: Net PP&E, opening | C22: =Inputs!$B$33 | D22: =C24 | E22: =D24 | F22: =E24 | G22: =F24
A23: D&A (opening PP&E + half of CapEx) / life | C23: =(C22+C21/2)/Inputs!$B$34 | D23: =(D22+D21/2)/Inputs!$B$34 | E23: =(E22+E21/2)/Inputs!$B$34 | F23: =(F22+F21/2)/Inputs!$B$34 | G23: =(G22+G21/2)/Inputs!$B$34
A24: Net PP&E, closing | C24: =C22+C21-C23 | D24: =D22+D21-D23 | E24: =E22+E21-E23 | F24: =F22+F21-F23 | G24: =G22+G21-G23
A25: EBIT | C25: =C20-C23 | D25: =D20-D23 | E25: =E20-E23 | F25: =F20-F23 | G25: =G20-G23
A26: Other income | C26: =C16*Inputs!$C$30 | D26: =D16*Inputs!$D$30 | E26: =E16*Inputs!$E$30 | F26: =F16*Inputs!$F$30 | G26: =G16*Inputs!$G$30
A27: Pre-tax income | C27: =C25+C26 | D27: =D25+D26 | E27: =E25+E26 | F27: =F25+F26 | G27: =G25+G26
A28: Net income | C28: =C27*(1-Inputs!$C$29) | D28: =D27*(1-Inputs!$D$29) | E28: =E27*(1-Inputs!$E$29) | F28: =F27*(1-Inputs!$F$29) | G28: =G27*(1-Inputs!$G$29)
A29: Diluted shares | B29: =Inputs!$B$11 | C29: =B29*(1+Inputs!$C$31) | D29: =C29*(1+Inputs!$D$31) | E29: =D29*(1+Inputs!$E$31) | F29: =E29*(1+Inputs!$F$31) | G29: =F29*(1+Inputs!$G$31)
A30: EPS | C30: =C28/C29 | D30: =D28/D29 | E30: =E28/E29 | F30: =F28/F29 | G30: =G28/G29
A31: Change in NWC | C31: =(C16-B16)*Inputs!$C$32 | D31: =(D16-C16)*Inputs!$D$32 | E31: =(E16-D16)*Inputs!$E$32 | F31: =(F16-E16)*Inputs!$F$32 | G31: =(G16-F16)*Inputs!$G$32
A32: Unlevered free cash flow | C32: =C25*(1-Inputs!$C$29)+C23-C21-C31 | D32: =D25*(1-Inputs!$D$29)+D23-D21-D31 | E32: =E25*(1-Inputs!$E$29)+E23-E21-E31 | F32: =F25*(1-Inputs!$F$29)+F23-F21-F31 | G32: =G25*(1-Inputs!$G$29)+G23-G21-G31
A34: Cost of capital
A35: Cost of equity (CAPM) | B35: =Inputs!$B$37+Inputs!$B$38*Inputs!$B$39
A36: After-tax cost of debt | B36: =Inputs!$B$40*(1-Inputs!$B$41)
A37: Equity weight | B37: =IF(Inputs!$B$42+Inputs!$B$43=0,1,Inputs!$B$42/(Inputs!$B$42+Inputs!$B$43))
A38: WACC | B38: ='Calc Base'!$B$37*'Calc Base'!$B$35+(1-'Calc Base'!$B$37)*'Calc Base'!$B$36+'Calc Base'!$B$9
A39: Cost of equity (scenario) | B39: ='Calc Base'!$B$35+'Calc Base'!$B$9
A41: DCF (stub year counted pro rata, mid-period discounting)
A42: Fiscal year | B42: FY2026A | C42: 2027 | D42: 2028 | E42: 2029 | F42: 2030 | G42: 2031
A43: Fiscal year end | C43: =Inputs!$C$19 | D43: =Inputs!$D$19 | E43: =Inputs!$E$19 | F43: =Inputs!$F$19 | G43: =Inputs!$G$19
A44: Years from price date to year end | C44: =(C43-Inputs!$B$7)/Inputs!$B$10 | D44: =(D43-Inputs!$B$7)/Inputs!$B$10 | E44: =(E43-Inputs!$B$7)/Inputs!$B$10 | F44: =(F43-Inputs!$B$7)/Inputs!$B$10 | G44: =(G43-Inputs!$B$7)/Inputs!$B$10
A45: Previous counted year end | C45: =0 | D45: =IF(C44>0,C44,0) | E45: =IF(D44>0,D44,0) | F45: =IF(E44>0,E44,0) | G45: =IF(F44>0,F44,0)
...

Sheet Calc Bull
A1: MU bull case: calculations
A2: All formulas. Inputs live on the Inputs tab.
A5: Scenario
A6: Growth delta | B6: =Inputs!$B$63
A7: Margin delta (by final year) | B7: =Inputs!$C$63
A8: Multiple factor | B8: =1+Inputs!$D$63
A9: WACC delta | B9: =Inputs!$E$63
A11: Projections
A12: Fiscal year | B12: FY2026A | C12: 2027 | D12: 2028 | E12: 2029 | F12: 2030 | G12: 2031
A13: Projection year | C13: =1 | D13: =C13+1 | E13: =D13+1 | F13: =E13+1 | G13: =F13+1
A14: Total: growth | C14: =Inputs!$C$64+'Calc Bull'!$B$6 | D14: =Inputs!$D$64+'Calc Bull'!$B$6 | E14: =Inputs!$E$64+'Calc Bull'!$B$6 | F14: =Inputs!$F$64+'Calc Bull'!$B$6 | G14: =Inputs!$G$64+'Calc Bull'!$B$6
A15: Total: revenue | B15: =Inputs!$B$23 | C15: =B15*(1+C14) | D15: =C15*(1+D14) | E15: =D15*(1+E14) | F15: =E15*(1+F14) | G15: =F15*(1+G14)
A16: Revenue | B16: =B15 | C16: =C15 | D16: =D15 | E16: =E15 | F16: =F15 | G16: =G15
A17: Revenue growth | C17: =C16/B16-1 | D17: =D16/C16-1 | E17: =E16/D16-1 | F17: =F16/E16-1 | G17: =G16/F16-1
A18: Margin delta ramp | C18: =C13/$G$13 | D18: =D13/$G$13 | E18: =E13/$G$13 | F18: =F13/$G$13 | G18: =G13/$G$13
A19: EBITDA margin | C19: =Inputs!$C$27+'Calc Bull'!$B$7*C18 | D19: =Inputs!$D$27+'Calc Bull'!$B$7*D18 | E19: =Inputs!$E$27+'Calc Bull'!$B$7*E18 | F19: =Inputs!$F$27+'Calc Bull'!$B$7*F18 | G19: =Inputs!$G$27+'Calc Bull'!$B$7*G18
A20: EBITDA | C20: =C16*C19 | D20: =D16*D19 | E20: =E16*E19 | F20: =F16*F19 | G20: =G16*G19
A21: CapEx | C21: =C16*Inputs!$C$28 | D21: =D16*Inputs!$D$28 | E21: =E16*Inputs!$E$28 | F21: =F16*Inputs!$F$28 | G21: =G16*Inputs!$G$28
A22: Net PP&E, opening | C22: =Inputs!$B$33 | D22: =C24 | E22: =D24 | F22: =E24 | G22: =F24
A23: D&A (opening PP&E + half of CapEx) / life | C23: =(C22+C21/2)/Inputs!$B$34 | D23: =(D22+D21/2)/Inputs!$B$34 | E23: =(E22+E21/2)/Inputs!$B$34 | F23: =(F22+F21/2)/Inputs!$B$34 | G23: =(G22+G21/2)/Inputs!$B$34
A24: Net PP&E, closing | C24: =C22+C21-C23 | D24: =D22+D21-D23 | E24: =E22+E21-E23 | F24: =F22+F21-F23 | G24: =G22+G21-G23
A25: EBIT | C25: =C20-C23 | D25: =D20-D23 | E25: =E20-E23 | F25: =F20-F23 | G25: =G20-G23
A26: Other income | C26: =C16*Inputs!$C$30 | D26: =D16*Inputs!$D$30 | E26: =E16*Inputs!$E$30 | F26: =F16*Inputs!$F$30 | G26: =G16*Inputs!$G$30
A27: Pre-tax income | C27: =C25+C26 | D27: =D25+D26 | E27: =E25+E26 | F27: =F25+F26 | G27: =G25+G26
A28: Net income | C28: =C27*(1-Inputs!$C$29) | D28: =D27*(1-Inputs!$D$29) | E28: =E27*(1-Inputs!$E$29) | F28: =F27*(1-Inputs!$F$29) | G28: =G27*(1-Inputs!$G$29)
A29: Diluted shares | B29: =Inputs!$B$11 | C29: =B29*(1+Inputs!$C$31) | D29: =C29*(1+Inputs!$D$31) | E29: =D29*(1+Inputs!$E$31) | F29: =E29*(1+Inputs!$F$31) | G29: =F29*(1+Inputs!$G$31)
A30: EPS | C30: =C28/C29 | D30: =D28/D29 | E30: =E28/E29 | F30: =F28/F29 | G30: =G28/G29
A31: Change in NWC | C31: =(C16-B16)*Inputs!$C$32 | D31: =(D16-C16)*Inputs!$D$32 | E31: =(E16-D16)*Inputs!$E$32 | F31: =(F16-E16)*Inputs!$F$32 | G31: =(G16-F16)*Inputs!$G$32
A32: Unlevered free cash flow | C32: =C25*(1-Inputs!$C$29)+C23-C21-C31 | D32: =D25*(1-Inputs!$D$29)+D23-D21-D31 | E32: =E25*(1-Inputs!$E$29)+E23-E21-E31 | F32: =F25*(1-Inputs!$F$29)+F23-F21-F31 | G32: =G25*(1-Inputs!$G$29)+G23-G21-G31
A34: Cost of capital
A35: Cost of equity (CAPM) | B35: =Inputs!$B$37+Inputs!$B$38*Inputs!$B$39
A36: After-tax cost of debt | B36: =Inputs!$B$40*(1-Inputs!$B$41)
A37: Equity weight | B37: =IF(Inputs!$B$42+Inputs!$B$43=0,1,Inputs!$B$42/(Inputs!$B$42+Inputs!$B$43))
A38: WACC | B38: ='Calc Bull'!$B$37*'Calc Bull'!$B$35+(1-'Calc Bull'!$B$37)*'Calc Bull'!$B$36+'Calc Bull'!$B$9
A39: Cost of equity (scenario) | B39: ='Calc Bull'!$B$35+'Calc Bull'!$B$9
A41: DCF (stub year counted pro rata, mid-period discounting)
A42: Fiscal year | B42: FY2026A | C42: 2027 | D42: 2028 | E42: 2029 | F42: 2030 | G42: 2031
A43: Fiscal year end | C43: =Inputs!$C$19 | D43: =Inputs!$D$19 | E43: =Inputs!$E$19 | F43: =Inputs!$F$19 | G43: =Inputs!$G$19
A44: Years from price date to year end | C44: =(C43-Inputs!$B$7)/Inputs!$B$10 | D44: =(D43-Inputs!$B$7)/Inputs!$B$10 | E44: =(E43-Inputs!$B$7)/Inputs!$B$10 | F44: =(F43-Inputs!$B$7)/Inputs!$B$10 | G44: =(G43-Inputs!$B$7)/Inputs!$B$10
A45: Previous counted year end | C45: =0 | D45: =IF(C44>0,C44,0) | E45: =IF(D44>0,D44,0) | F45: =IF(E44>0,E44,0) | G45: =IF(F44>0,F44,0)
...

Sheet Calc Bear
A1: MU bear case: calculations
A2: All formulas. Inputs live on the Inputs tab.
A5: Scenario
A6: Growth delta | B6: =Inputs!$B$65
A7: Margin delta (by final year) | B7: =Inputs!$C$65
A8: Multiple factor | B8: =1+Inputs!$D$65
A9: WACC delta | B9: =Inputs!$E$65
A11: Projections
A12: Fiscal year | B12: FY2026A | C12: 2027 | D12: 2028 | E12: 2029 | F12: 2030 | G12: 2031
A13: Projection year | C13: =1 | D13: =C13+1 | E13: =D13+1 | F13: =E13+1 | G13: =F13+1
A14: Total: growth | C14: =Inputs!$C$66+'Calc Bear'!$B$6 | D14: =Inputs!$D$66+'Calc Bear'!$B$6 | E14: =Inputs!$E$66+'Calc Bear'!$B$6 | F14: =Inputs!$F$66+'Calc Bear'!$B$6 | G14: =Inputs!$G$66+'Calc Bear'!$B$6
A15: Total: revenue | B15: =Inputs!$B$23 | C15: =B15*(1+C14) | D15: =C15*(1+D14) | E15: =D15*(1+E14) | F15: =E15*(1+F14) | G15: =F15*(1+G14)
A16: Revenue | B16: =B15 | C16: =C15 | D16: =D15 | E16: =E15 | F16: =F15 | G16: =G15
A17: Revenue growth | C17: =C16/B16-1 | D17: =D16/C16-1 | E17: =E16/D16-1 | F17: =F16/E16-1 | G17: =G16/F16-1
A18: Margin delta ramp | C18: =C13/$G$13 | D18: =D13/$G$13 | E18: =E13/$G$13 | F18: =F13/$G$13 | G18: =G13/$G$13
A19: EBITDA margin | C19: =Inputs!$C$27+'Calc Bear'!$B$7*C18 | D19: =Inputs!$D$27+'Calc Bear'!$B$7*D18 | E19: =Inputs!$E$27+'Calc Bear'!$B$7*E18 | F19: =Inputs!$F$27+'Calc Bear'!$B$7*F18 | G19: =Inputs!$G$27+'Calc Bear'!$B$7*G18
A20: EBITDA | C20: =C16*C19 | D20: =D16*D19 | E20: =E16*E19 | F20: =F16*F19 | G20: =G16*G19
A21: CapEx | C21: =C16*Inputs!$C$28 | D21: =D16*Inputs!$D$28 | E21: =E16*Inputs!$E$28 | F21: =F16*Inputs!$F$28 | G21: =G16*Inputs!$G$28
A22: Net PP&E, opening | C22: =Inputs!$B$33 | D22: =C24 | E22: =D24 | F22: =E24 | G22: =F24
A23: D&A (opening PP&E + half of CapEx) / life | C23: =(C22+C21/2)/Inputs!$B$34 | D23: =(D22+D21/2)/Inputs!$B$34 | E23: =(E22+E21/2)/Inputs!$B$34 | F23: =(F22+F21/2)/Inputs!$B$34 | G23: =(G22+G21/2)/Inputs!$B$34
A24: Net PP&E, closing | C24: =C22+C21-C23 | D24: =D22+D21-D23 | E24: =E22+E21-E23 | F24: =F22+F21-F23 | G24: =G22+G21-G23
A25: EBIT | C25: =C20-C23 | D25: =D20-D23 | E25: =E20-E23 | F25: =F20-F23 | G25: =G20-G23
A26: Other income | C26: =C16*Inputs!$C$30 | D26: =D16*Inputs!$D$30 | E26: =E16*Inputs!$E$30 | F26: =F16*Inputs!$F$30 | G26: =G16*Inputs!$G$30
A27: Pre-tax income | C27: =C25+C26 | D27: =D25+D26 | E27: =E25+E26 | F27: =F25+F26 | G27: =G25+G26
A28: Net income | C28: =C27*(1-Inputs!$C$29) | D28: =D27*(1-Inputs!$D$29) | E28: =E27*(1-Inputs!$E$29) | F28: =F27*(1-Inputs!$F$29) | G28: =G27*(1-Inputs!$G$29)
A29: Diluted shares | B29: =Inputs!$B$11 | C29: =B29*(1+Inputs!$C$31) | D29: =C29*(1+Inputs!$D$31) | E29: =D29*(1+Inputs!$E$31) | F29: =E29*(1+Inputs!$F$31) | G29: =F29*(1+Inputs!$G$31)
A30: EPS | C30: =C28/C29 | D30: =D28/D29 | E30: =E28/E29 | F30: =F28/F29 | G30: =G28/G29
A31: Change in NWC | C31: =(C16-B16)*Inputs!$C$32 | D31: =(D16-C16)*Inputs!$D$32 | E31: =(E16-D16)*Inputs!$E$32 | F31: =(F16-E16)*Inputs!$F$32 | G31: =(G16-F16)*Inputs!$G$32
A32: Unlevered free cash flow | C32: =C25*(1-Inputs!$C$29)+C23-C21-C31 | D32: =D25*(1-Inputs!$D$29)+D23-D21-D31 | E32: =E25*(1-Inputs!$E$29)+E23-E21-E31 | F32: =F25*(1-Inputs!$F$29)+F23-F21-F31 | G32: =G25*(1-Inputs!$G$29)+G23-G21-G31
A34: Cost of capital
A35: Cost of equity (CAPM) | B35: =Inputs!$B$37+Inputs!$B$38*Inputs!$B$39
A36: After-tax cost of debt | B36: =Inputs!$B$40*(1-Inputs!$B$41)
A37: Equity weight | B37: =IF(Inputs!$B$42+Inputs!$B$43=0,1,Inputs!$B$42/(Inputs!$B$42+Inputs!$B$43))
A38: WACC | B38: ='Calc Bear'!$B$37*'Calc Bear'!$B$35+(1-'Calc Bear'!$B$37)*'Calc Bear'!$B$36+'Calc Bear'!$B$9
A39: Cost of equity (scenario) | B39: ='Calc Bear'!$B$35+'Calc Bear'!$B$9
A41: DCF (stub year counted pro rata, mid-period discounting)
A42: Fiscal year | B42: FY2026A | C42: 2027 | D42: 2028 | E42: 2029 | F42: 2030 | G42: 2031
A43: Fiscal year end | C43: =Inputs!$C$19 | D43: =Inputs!$D$19 | E43: =Inputs!$E$19 | F43: =Inputs!$F$19 | G43: =Inputs!$G$19
A44: Years from price date to year end | C44: =(C43-Inputs!$B$7)/Inputs!$B$10 | D44: =(D43-Inputs!$B$7)/Inputs!$B$10 | E44: =(E43-Inputs!$B$7)/Inputs!$B$10 | F44: =(F43-Inputs!$B$7)/Inputs!$B$10 | G44: =(G43-Inputs!$B$7)/Inputs!$B$10
A45: Previous counted year end | C45: =0 | D45: =IF(C44>0,C44,0) | E45: =IF(D44>0,D44,0) | F45: =IF(E44>0,E44,0) | G45: =IF(F44>0,F44,0)
...

Sheet Monte Carlo
A1: Monte Carlo: base-case price target distribution
A2: Script output (values, not formulas): 2,000 runs of the model engine, seed 7. Growth, margin, multiple and WACC deltas are drawn from normal distributions with the bull and bear cases at about the 90th and 10th percentiles.
A4: Assumption | B4: Std dev
A5: growth delta | B5: 0.10166199
A6: margin delta | B6: 0.1170412
A7: multiple delta | B7: 0.1755618
A8: wacc delta | B8: 0.0039013733
A10: Result
A11: Current price | B11: 1062.29
A12: Mean price target | B12: 1266.7042
A13: P5 | B13: 748.87647
A14: P10 | B14: 830.94738
A15: P25 | B15: 986.0837
A16: P50 | B16: 1199.8146
A17: P75 | B17: 1474.2764
A18: P90 | B18: 1796.7155
A19: P95 | B19: 1993.6759
A20: Chance the target is above today's price | B20: 0.666
A21: Chance the total return beats the S&P 500 benchmark | B21: 0.5375
A23: Price target bucket (from) | B23: Runs
A24: 447.82 | B24: 15
A25: 584.04 | B25: 55
A26: 720.26 | B26: 173
A27: 856.48 | B27: 268
A28: 992.7 | B28: 325
A29: 1128.93 | B29: 296
A30: 1265.15 | B30: 253
A31: 1401.37 | B31: 190
A32: 1537.59 | B32: 142
A33: 1673.81 | B33: 91
A34: 1810.03 | B34: 76
A35: 1946.25 | B35: 42
... A43: 3036.02 | B43: 1

Sheet Value Drivers
A1: Value drivers: base price target, one input at a time
A2: Script output (values). Largest swing first: these are the assumptions the thesis leans on.
A4: Driver | B4: Low case | C4: PT (low) | D4: High case | E4: PT (high) | F4: Swing | G4: Base PT
A5: Target and exit multiples | B5: -10% | C5: 1149.7642 | D5: +10% | E5: 1335.0473 | F5: 185.28313 | G5: 1242.4057
A6: Revenue growth (every year) | B6: -1 pt | C6: 1212.9287 | D6: +1 pt | E6: 1272.5846 | F6: 59.655913 | G6: 1242.4057
A7: EBITDA margin (by final year) | B7: -1 pt | C7: 1230.3992 | D7: +1 pt | E7: 1254.4123 | F7: 24.013073 | G7: 1242.4057
A8: Tax rate | B8: +1 pt | C8: 1235.3719 | D8: -1 pt | E8: 1249.4395 | F8: 14.067644 | G8: 1242.4057
A9: CapEx % revenue | B9: +1 pt | C9: 1235.8878 | D9: -1 pt | E9: 1248.9236 | F9: 13.03581 | G9: 1242.4057
A10: WACC | B10: +0.5 pt | C10: 1236.061 | D10: -0.5 pt | E10: 1248.8807 | F10: 12.819731 | G10: 1242.4057
